Traceback (most recent call last):
  File "/home/george/drought-311-venv/lib64/python3.11/site-packages/nbclient/client.py", line 782, in _async_poll_for_reply
    msg = await ensure_async(self.kc.shell_channel.get_msg(timeout=new_timeout))
          ^^^^^^^^^^^^^^^^^^^^^^^^^^^^^^^^^^^^^^^^^^^^^^^^^^^^^^^^^^^^^^^^^^^^^^
  File "/home/george/drought-311-venv/lib64/python3.11/site-packages/jupyter_core/utils/__init__.py", line 198, in ensure_async
    result = await obj
             ^^^^^^^^^
  File "/home/george/drought-311-venv/lib64/python3.11/site-packages/jupyter_client/channels.py", line 230, in get_msg
    raise Empty
_queue.Empty

During handling of the above exception, another exception occurred:

Traceback (most recent call last):
  File "/home/george/drought-311-venv/lib64/python3.11/site-packages/jupyter_cache/executors/utils.py", line 58, in single_nb_execution
    executenb(
  File "/home/george/drought-311-venv/lib64/python3.11/site-packages/nbclient/client.py", line 1314, in execute
    return NotebookClient(nb=nb, resources=resources, km=km, **kwargs).execute()
           ^^^^^^^^^^^^^^^^^^^^^^^^^^^^^^^^^^^^^^^^^^^^^^^^^^^^^^^^^^^^^^^^^^^^^
  File "/home/george/drought-311-venv/lib64/python3.11/site-packages/jupyter_core/utils/__init__.py", line 165, in wrapped
    return loop.run_until_complete(inner)
           ^^^^^^^^^^^^^^^^^^^^^^^^^^^^^^
  File "/usr/lib64/python3.11/asyncio/base_events.py", line 654, in run_until_complete
    return future.result()
           ^^^^^^^^^^^^^^^
  File "/home/george/drought-311-venv/lib64/python3.11/site-packages/nbclient/client.py", line 709, in async_execute
    await self.async_execute_cell(
  File "/home/george/drought-311-venv/lib64/python3.11/site-packages/nbclient/client.py", line 1005, in async_execute_cell
    exec_reply = await self.task_poll_for_reply
                 ^^^^^^^^^^^^^^^^^^^^^^^^^^^^^^
  File "/home/george/drought-311-venv/lib64/python3.11/site-packages/nbclient/client.py", line 806, in _async_poll_for_reply
    error_on_timeout_execute_reply = await self._async_handle_timeout(timeout, cell)
                                     ^^^^^^^^^^^^^^^^^^^^^^^^^^^^^^^^^^^^^^^^^^^^^^^
  File "/home/george/drought-311-venv/lib64/python3.11/site-packages/nbclient/client.py", line 856, in _async_handle_timeout
    raise CellTimeoutError.error_from_timeout_and_cell(
nbclient.exceptions.CellTimeoutError: A cell timed out while it was being executed, after 500 seconds.
The message was: Cell execution timed out.
Here is a preview of the cell contents:
-------------------
['dataset = "reanalysis-era5-land-monthly-means"', 'request = {', "    'product_type': ['monthly_averaged_reanalysis'],", "    'variable': ['2m_temperature', 'skin_temperature', 'soil_temperature_level_1', 'soil_temperature_level_2', 'soil_temperature_level_3', 'soil_temperature_level_4', ", "                 'volumetric_soil_water_layer_1', 'volumetric_soil_water_layer_2', 'volumetric_soil_water_layer_3', 'volumetric_soil_water_layer_4',"]
...
["    'area': [-9.95, 40.23, -26.8, 52.45]", '}', '', "# client.retrieve(dataset, request, 'era5-land-monthly-means-madagascar-2018-2024.nc')", 'client.retrieve(dataset, request).download()']
-------------------

